Workbook

Sheet Guide
A1: 명탐정 코난 TCG 카드 데이터 (cards.xlsx)
A3: 사용법 | B3: Cards 시트에서 카드 ID 를 검색(Ctrl+F)해 셀을 고치고 저장 → GitHub 에 올리면 자동 검증/변환/배포됩니다.
A4: 연결 키 | B4: 항상 카드 ID(id / card_id). 행 순서·정렬은 마음대로 바꿔도 됩니다.
A5: 시트 | B5: Cards=카드 기본 정보 / Abilities=능력(ab) 1개당 1행 / Ops=능력 안의 효과(primitive) 1개당 1행 / CardExtra=추가 필드 / Meta=최상위 항목
A6: 이미지 | B6: 이미지는 실제 파일로 관리합니다 (CardImage 폴더의 id_XXXX.jpg). Cards 시트의 image_file 열에 파일명을 적으면 게임에 반영됩니다 (cards.json 에는 경로만 저장, base64 없음). 새 이미지는 CardImage 폴더에 넣고 image_file 만 적으세요.
A7: own(소유자) | B7: 굵은 발동 조건/코스트(Abilities 의 cond/cost)에서 own 이 없으면 자기 쪽(self)입니다. 실제 효과 대상은 Ops 시트의 filter_own 열(self/opp/any 드롭다운)에서 관리합니다. 비워 두면 '미지정'으로 검증이 경고합니다.
A8: 메모 열 | B8: 열 이름 앞에 # 또는 _ 를 붙이면 변환 시 무시됩니다.
A10: 머리글 색 | B10: 의미
A11: 파랑 | B11: 연결 키(ID/번호) — 바꾸지 마세요 | C11: key
A12: 주황 | B12: 엔진 동작에 영향을 주는 값(색/AP/LP/효과 등) | C12: logic
A13: 초록 | B13: 표시용 텍스트 — 고쳐도 게임 로직은 바뀌지 않음 | C13: display
A14: 노랑 | B14: 참고용 메타데이터 | C14: meta
A15: 회색 | B15: 자동 계산 열 — 수정해도 무시됨 | C15: readonly
A17: 필드 | B17: 설명 / 구분
A18: id | B18: 카드 ID (연결 키, 바꾸지 마세요) | C18: 연결 키
A19: type | B19: 카드 종류 char/event/partner/case | C19: 엔진 동작
A20: color | B20: 색상 (여러 색은 / 로 연결) | C20: 엔진 동작
A21: lv | B21: 레벨 = FILE 코스트 | C21: 엔진 동작
A22: lv2 | B22: 사건 카드의 해결편 레벨 | C22: 엔진 동작
A23: ap | B23: AP (공격력) | C23: 엔진 동작
A24: lp | B24: LP (라이프) | C24: 엔진 동작
A25: kw | B25: 키워드 (assault, misread1, disguise, rapid, bullet …) | C25: 엔진 동작
A26: trait | B26: 특징 (쉼표로 구분) | C26: 엔진 동작
A27: n | B27: 카드명 | C27: 표시용
A28: fx | B28: 일본어 원문 효과 텍스트 (표시용, 엔진 동작에 영향 없음) | C28: 표시용
A29: extra | B29: 한국어 효과 설명 (표시용, 엔진 동작에 영향 없음) | C29: 표시용
... A48: params | B48: 효과 매개변수 (JSON 객체, 하위 ops 포함) | C48: 엔진 동작

Sheet Cards
A1: id | B1: type | C1: color | D1: lv | E1: lv2 | F1: ap | G1: lp | H1: kw | I1: trait | J1: n | K1: series | L1: fx | M1: extra | N1: image_file | O1: ab_count | P1: img_info
A2: id_0001 | B2: char | C2: blue | D2: 8 | F2: 7000 | G2: 2 | I2: 探偵,毛利探偵事務所,少年探偵団 | J2: 江戸川コナン | K2: P01 | L2: 【パートナー(青)】【ターン①】自分がネクストヒントで手札を使用したとき、そのカードのレベル以下のレベルのキャラを1枚まで選び、デッキの下に移す。 | M2: 【파트너(청)】【턴①】 자신이 넥스트 힌트로 손패를 사용했을 때, 그 카드의 레벨 이하의 레벨을 가진 캐릭터를 1장까지 골라 덱 아래로 옮긴다. | N2: id_0001.jpg | O2: =COUNTIF(Abilities!$A:$A,A2) -> 1 | P2: 716x1000 216KB
A3: id_0002 | B3: char | C3: blue | D3: 6 | F3: 4000 | G3: 1 | I3: 少年探偵団,科学者 | J3: 灰原哀 | K3: P01 | L3: 【絆】江戸川コナン 相手の能力や効果によって選ばれない。 【宣言】【スリープ】:手札からレベル5以下の特徴[少年探偵団]のキャラを1枚まで登場させる。カード名[江戸川コナン]を登場させた場合、カードを1枚引く。 | M3: 【인연】에도가와 코난: 상대의 능력이나 효과로 선택되지 않는다. 【선언】【슬립】: 손패에서 레벨 5 이하의 특징 [소년탐정단]인 캐릭터를 1장까지 등장시킨다. 카드명 [에도가와 코난]을 등장시킨 경우, 카드를 1장 뽑는다. | N3: id_0002.jpg | O3: =COUNTIF(Abilities!$A:$A,A3) -> 2 | P3: 716x1000 208KB
A4: id_0003 | B4: char | C4: blue | D4: 7 | F4: 6000 | G4: 0 | I4: 高校生,毛利探偵事務所,空手家 | J4: 毛利蘭 | K4: P01 | L4: 相手の現場にいるキャラがこのキャラとのコンタクトによってリムーブされたとき、 カードを1枚引く。 【パートナー(青)】【宣言】【ターン①】手札を1枚リムーブする：ターン終了時までこのキャラをAP＋1000し､突撃(登場したターンからすぐにアクションできる)を持つ。 | M4: 상대의 현장에 있는 캐릭터가 이 캐릭터와의 컨택트로 인해 리무브되었을 때, 카드를 1장 뽑는다. 【파트너(파랑)】【선언】【턴①】 손패를 1장 리무브한다: 턴 종료 시까지 이 캐릭터의 AP를 +1000 하고, 돌격(등장한 턴부터 바로 액션할 수 있다)을 얻는다. | N4: id_0003.jpg | O4: =COUNTIF(Abilities!$A:$A,A4) -> 2 | P4: 716x1000 210KB
A5: id_0004 | B5: char | C5: blue | D5: 5 | F5: 6000 | G5: 1 | I5: 探偵,毛利探偵事務所,少年探偵団 | J5: 江戸川コナン | K5: P01 | L5: 【ヒラメキ】(証拠からリムーブされるときに発動する) カードを1枚引く。 | M5: 【히라메키】(증거에서 리무브될 때 발동한다) 카드를 1장 뽑는다. | N5: id_0004.jpg | O5: =COUNTIF(Abilities!$A:$A,A5) -> 1 | P5: 716x1000 156KB
A6: id_0005 | B6: char | C6: blue | D6: 6 | F6: 5000 | G6: 1 | I6: 探偵,高校生 | J6: 工藤新一 | K6: P01 | L6: 【パートナー】【青】お互いの現場にキャラが合わせて6枚以上いる場合、手札にあるこのキャラはレベル4になる。 【宣言】デッキの下に移す:LP0以下の【青】のキャラを1枚まで選び、アクティブにする。 | M6: 【파트너】【청】 서로의 현장에 캐릭터가 합쳐서 6장 이상 있는 경우, 손패에 있는 이 캐릭터는 레벨 4가 된다. 【선언】덱 아래로 옮긴다: LP0 이하의 【청】 캐릭터를 1장까지 선택하고, 액티브로 한다. | N6: id_0005.jpg | O6: =COUNTIF(Abilities!$A:$A,A6) -> 2 | P6: 716x1000 179KB
A7: id_0006 | B7: char | C7: blue | D7: 6 | F7: 6000 | G7: 0 | I7: 探偵,毛利探偵事務所 | J7: 毛利小五郎 | K7: P01 | L7: 相手の現場にいるキャラがこのキャラとのコンタクトによってリムーブされたとき、 手札を1枚リムーブしてもよい。そうした場合、自分は証拠を1つ得る。 | M7: 상대의 현장에 있는 캐릭터가 이 캐릭터와의 컨택트로 인해 리무브되었을 때, 손패를 1장 리무브해도 된다. 그렇게 한 경우, 자신은 증거를 1개 얻는다. | N7: id_0006.jpg | O7: =COUNTIF(Abilities!$A:$A,A7) -> 1 | P7: 716x1000 164KB
A8: id_0007 | B8: char | C8: blue | D8: 4 | F8: 2000 | G8: 2 | I8: 探偵,毛利探偵事務所,少年探偵団 | J8: 江戸川コナン | K8: P01 | L8: このキャラはスリープ状態で登場する。 【ヒラメキ】(証拠からリムーブされるときに発動する)カードを1枚引く。 | M8: 이 캐릭터는 슬립 상태로 등장한다. 【히라메키】(증거에서 리무브될 때 발동한다) 카드를 1장 뽑는다. | N8: id_0007.jpg | O8: =COUNTIF(Abilities!$A:$A,A8) -> 2 | P8: 716x1000 191KB
A9: id_0008 | B9: char | C9: blue | D9: 7 | F9: 6000 | G9: 1 | I9: 発明家 | J9: 阿笠博士 | K9: P01 | L9: 【ターン①】能力や効果によってレベル6以下の特徴[少年探偵団]のキャラが自分の現場に登場したとき、その中から1枚をアクティブにし、ターン終了時までそのキャラに迅速(登場したターンからすぐに推理かアクションできる)を与える。 | M9: 【턴①】능력이나 효과에 의해 레벨 6 이하의 특징 [소년탐정단]의 캐릭터가 자신의 현장에 登場했을 때, 그중에서 1장을 액티브로 하고, 턴 종료 시까지 그 캐릭터에게 신속(登場한 턴부터 바로 추리나 액션을 할 수 있다)을 부여한다. | N9: id_0008.jpg | O9: =COUNTIF(Abilities!$A:$A,A9) -> 1 | P9: 716x1000 249KB
A10: id_0009 | B10: char | C10: blue | D10: 4 | F10: 3000 | G10: 1 | I10: 弁護士 | J10: 妃英理 | K10: P01 | L10: 【登場時】自分のデッキのカードを上から2枚見る。その中からLP0の【青】のキャラを1枚まで公開して手札に加え、残りを好きな順番でデッキの下に移す。 | M10: 【등장 시】자신의 덱 카드를 위에서 2장 본다. 그중에서 LP0의 【청】 캐릭터를 1장까지 공개하여 손패에 넣고, 나머지는 원하는 순서로 덱 아래로 옮긴다. | N10: id_0009.jpg | O10: =COUNTIF(Abilities!$A:$A,A10) -> 1 | P10: 716x1000 162KB
A11: id_0010 | B11: char | C11: blue | D11: 4 | F11: 5000 | G11: 0 | I11: 少年探偵団 | J11: 小嶋元太 | K11: P01 | L11: 【登場時】レベル3以上のキャラの能力やレベル3以上のイベントの効果によって登場した場合、レベル5以下のキャラを1枚まで選び、スリープさせる。 | M11: 【등장 시】레벨 3 이상의 캐릭터의 능력이나 레벨 3 이상의 이벤트의 효과로 등장한 경우, 레벨 5 이하의 캐릭터를 1장까지 선택하여 슬리프시킨다. | N11: id_0010.jpg | O11: =COUNTIF(Abilities!$A:$A,A11) -> 1 | P11: 716x1000 195KB
A12: id_0011 | B12: char | C12: blue | D12: 3 | F12: 3000 | G12: 1 | I12: 少年探偵団 | J12: 円谷光彦 | K12: P01 | L12: 【登場時】レベル3以上のキャラの能力やレベル3以上のイベントの効果によって登場した場合、キャラを1枚まで選び、ターン終了時までAP+2000する。 | M12: 【등장 시】레벨 3 이상의 캐릭터의 능력이나 레벨 3 이상의 이벤트의 효과로 등장한 경우, 캐릭터를 1장까지 선택하고, 턴 종료 시까지 AP+2000 한다. | N12: id_0011.jpg | O12: =COUNTIF(Abilities!$A:$A,A12) -> 1 | P12: 716x1000 214KB
A13: id_0012 | B13: char | C13: blue | D13: 4 | F13: 4000 | G13: 1 | I13: 少年探偵団,科学者 | J13: 灰原哀 | K13: D01 | L13: 【登場時】自分のデッキのカードを上から4枚見る。その中から【青】のカードを1枚まで公開して手札に加え、残りを好きな順番でデッキの下に移す。カードを手札に加えた場合、手札を1枚リムーブする。 【ヒラメキ】(証拠からリムーブされるときに発動する)カードを1枚引く。 | M13: 【등장 시】자신의 덱 위에서 카드를 4장 본다. 그중에서 【파랑】 카드를 1장까지 공개하여 손패에 넣고, 나머지는 원하는 순서로 덱 아래로 보낸다. 카드를 손패에 넣은 경우, 손패를 1장 리무브한다. 【번뜩임】(증거에서 리무브될 때 발동한다) 카드를 1장 뽑는다. | N13: id_0012.jpg | O13: =COUNTIF(Abilities!$A:$A,A13) -> 2 | P13: 716x1000 251KB
... A18: id_0017 | B18: char | C18: blue | D18: 3 | F18: 2000 | G18: 1 | I18: 少年探偵団 | J18: 吉田歩美 | K18: P01 | L18: 【登場時】レベル3以上のキャラの能力やレベル3以上のイベントの効果によって登場した場合、カードを1枚引く。 | M18: 【등장 시】 레벨 3 이상의 캐릭터의 능력이나 레벨 3 이상의 이벤트의 효과로 등장한 경우, 카드를 1장 뽑는다. | N18: id_0017.jpg | O18: =COUNTIF(Abilities!$A:$A,A18) -> 1 | P18: 716x1000 211KB
A19: id_0018 | B19: event | C19: blue | D19: 6 | J19: 少年探偵団 | K19: P01 | L19: 【パートナー】【青】手札を1枚リムーブする。自分のデッキのカードを上から6枚見る。その中からレベル4以下の特徴[少年探偵団]のキャラを2枚まで登場させ、残りをシャッフルしてデッキの下に移す。 | M19: 【파트너】【청】 손패를 1장 리무브한다. 자신의 덱 카드를 위에서 6장 본다. 그중에서 레벨 4 이하의 특징 [소년탐정단]을 가진 캐릭터를 2장까지 등장시키고, 나머지는 셔플해서 덱 아래로 옮긴다. | N19: id_0018.jpg | O19: =COUNTIF(Abilities!$A:$A,A19) -> 1 | P19: 716x1000 257KB
A20: id_0019 | B20: event | C20: blue | D20: 2 | J20: シャッフルロマンス | K20: P01 | L20: 自分のデッキのカードを上から5枚見る。その中からカードを1枚まで手札に加え、残りを好きな順番でデッキの下に移す。このイベントを自分の現場にいるキャラ1枚にセットする。 このイベントがセットされているキャラは「このキャラがコンタクトしたとき、そのコンタクト中、このキャラをAP+2000する。」を持つ。 【ヒラメキ】(証拠からリムーブされるときに発動する) カードを1枚引く。 | M20: 자신의 덱 카드를 위에서 5장 본다. 그 중에서 카드를 1장까지 손패에 추가하고, 나머지는 원하는 순서로 덱 아래로 옮긴다. 이 이벤트를 자신의 현장에 있는 캐릭터 1장에 세트한다. 이 이벤트가 세트되어 있는 캐릭터는 "이 캐릭터가 컨택트했을 때, 그 컨택트 중, 이 캐릭터를 AP+2000 한다."를 가진다. 【히라메키】(증거에서 리무브될 때 발동한다) 카드를 1장 뽑는다. | N20: id_0019.jpg | O20: =COUNTIF(Abilities!$A:$A,A20) -> 3 | P20: 716x1000 202KB
A21: id_0020 | B21: case | C21: blue | D21: 7 | E21: 6 | J21: 大阪“3つのK”事件 | K21: P01 | N21: id_0020.jpg | O21: =COUNTIF(Abilities!$A:$A,A21) -> 0 | P21: 1000x716 150KB
A22: id_0021 | B22: char | C22: green | D22: 7 | F22: 5000 | G22: 0 | I22: 高校生 | J22: 遠山和葉 | K22: P01 | L22: 【パートナー(緑)】LP+1 【宣言】【スリープ】：カード名［服部平次］のキャラを1枚まで選び、ターン終了時まで突撃（登場したターンからすぐにアクションできる）を与える。 | M22: 【파트너(녹)】 LP+1 【선언】【슬립】: 카드명 [핫토리 헤이지]인 캐릭터를 1장까지 선택하고, 턴 종료 시까지 돌격(등장한 턴부터 바로 액션할 수 있다)을 부여한다. | N22: id_0021.jpg | O22: =COUNTIF(Abilities!$A:$A,A22) -> 2 | P22: 716x1000 223KB
A23: id_0022 | B23: char | C23: green | D23: 8 | F23: 7000 | G23: 2 | I23: 探偵,高校生 | J23: 服部平次 | K23: P01 | L23: このキャラは相手の現場にいるアクティブ状態のキャラを指定してアクションできる。 このキャラがコンタクトしたとき、そのコンタクト中、このキャラをAP＋1000する。 【パートナー(緑)】【自分ターン中】【ターン①】このキャラがコンタクトしたとき、このキャラをアクティブにする。 | M23: 이 캐릭터는 상대의 현장에 있는 액티브 상태의 캐릭터를 지정하여 액션할 수 있다. 이 캐릭터가 컨택트했을 때, 그 컨택트 중 이 캐릭터의 AP를 +1000 한다. 【파트너(녹)】【자신 턴 중】【턴①】 이 캐릭터가 컨택트했을 때, 이 캐릭터를 액티브로 한다. | N23: id_0022.jpg | O23: =COUNTIF(Abilities!$A:$A,A23) -> 3 | P23: 716x1000 211KB
A24: id_0023 | B24: char | C24: green | D24: 5 | F24: 6000 | G24: 1 | I24: 探偵,高校生 | J24: 服部平次 | K24: P01 | L24: 【ヒラメキ】(証拠からリムーブされるときに発動する)カードを1枚引く。 | M24: 【히라메키】(증거에서 리무브될 때 발동한다) 카드를 1장 뽑는다. | N24: id_0023.jpg | O24: =COUNTIF(Abilities!$A:$A,A24) -> 1 | P24: 716x1000 176KB
A25: id_0024 | B25: char | C25: green | D25: 5 | F25: 4000 | G25: 1 | I25: 高校生 | J25: 大岡紅葉 | K25: P01 | L25: 【ターン①】相手の現場にいるキャラがコンタクトによってリムーブされたとき、自分のリムーブエリアにある【カットイン】を持つ【緑】のカードを1枚まで選び、手札に加える。 | M25: 【턴①】 상대의 현장에 있는 캐릭터가 컨택트로 인해 리무브되었을 때, 자신의 리무브 에리어에 있는 【컷인】을 가진 【녹색】 카드를 1장까지 선택하여 손패에 넣는다. | N25: id_0024.jpg | O25: =COUNTIF(Abilities!$A:$A,A25) -> 1 | P25: 716x1000 236KB
A26: id_0025 | B26: char | C26: green | D26: 6 | F26: 5000 | G26: 1 | I26: 執事 | J26: 伊織無我 | K26: P01 | L26: 相手の現場にいるキャラがコンタクトによってリムーブされたとき、ターン終了時までこのキャラは突撃（登場したターンからすぐにアクションできる）を持つ。 | M26: 상대의 현장에 있는 캐릭터가 콘택트에 의해 리무브되었을 때, 턴 종료 시까지 이 캐릭터는 돌격(등장한 턴부터 바로 액션할 수 있다)을 가진다. | N26: id_0025.jpg | O26: =COUNTIF(Abilities!$A:$A,A26) -> 1 | P26: 716x1000 202KB
A27: id_0026 | B27: char | C27: green | D27: 3 | F27: 3000 | G27: 1 | I27: 探偵,高校生 | J27: 服部平次 | K27: D06 | L27: 【ターン①】このキャラがアクション［キャラ］したとき、ターン終了時までこのキャラをAP+1000する。 | M27: 【턴①】이 캐릭터가 액션[캐릭터]을 했을 때, 턴 종료 시까지 이 캐릭터를 AP+1000 한다. | N27: id_0026.jpg | O27: =COUNTIF(Abilities!$A:$A,A27) -> 1 | P27: 716x1000 203KB
A28: id_0027 | B28: char | C28: green | D28: 2 | F28: 1000 | G28: 1 | I28: 高校生 | J28: 遠山和葉 | L28: 【カットイン】AP＋2000（コンタクト中に手札からリムーブして使う） | M28: 【컷인】AP+2000 (컨택트 중에 손패에서 리무브하여 사용한다) | N28: id_0027.jpg | O28: =COUNTIF(Abilities!$A:$A,A28) -> 1 | P28: 716x1000 191KB
A29: id_0028 | B29: char | C29: green | D29: 4 | F29: 4000 | G29: 1 | I29: 高校生 | J29: 大岡紅葉 | K29: P01 | L29: 【登場時】自分のデッキのカードを上から4枚見る。その中から【緑】のカードを1枚まで公開して手札に加え、残りを好きな順番でデッキの下に移す。カードを手札に加えた場合、手札を1枚リムーブする。 【ヒラメキ】(証拠からリムーブされるときに発動する)カードを1枚引く。 | M29: 【등장 시】자신의 덱 카드를 위에서 4장 본다. 그중에서 【녹색】 카드를 1장까지 공개하여 손패에 더하고, 나머지는 원하는 순서로 덱 아래로 옮긴다. 카드를 손패에 더한 경우, 손패를 1장 리무브한다. 【힌트(번뜩임)】(증거에서 리무브될 때 발동한다) 카드를 1장 뽑는다. | N29: id_0028.jpg | O29: =COUNTIF(Abilities!$A:$A,A29) -> 2 | P29: 716x1000 221KB
A30: id_0029 | B30: char | C30: green | D30: 4 | F30: 4000 | G30: 1 | I30: 警察,大阪府警 | J30: 大滝悟郎 | K30: D06 | L30: 【現場リムーブ時】コンタクトによってリムーブされた場合、キャラを1枚まで選び、スリープさせる。 【ヒラメキ】(証拠からリムーブされるときに発動する)カードを1枚引く。 | M30: 【현장 리무브 시】 컨택트에 의해 리무브된 경우, 캐릭터를 1장까지 선택해 슬리프시킨다. 【히라메키】(증거에서 리무브될 때 발동한다) 카드를 1장 뽑는다. | N30: id_0029.jpg | O30: =COUNTIF(Abilities!$A:$A,A30) -> 2 | P30: 716x1000 184KB
A31: id_0030 | B31: char | C31: green | D31: 6 | F31: 6000 | G31: 1 | I31: 警察,大阪府警 | J31: 遠山銀司郎 | K31: P01 | L31: 【ターン①】自分の現場にいる【緑】のキャラがアクション[キャラ]したとき、キャラを1枚まで選び、スリープさせる。 | M31: 【턴①】자신의 현장에 있는 【녹】 캐릭터가 액션[캐릭터]했을 때, 캐릭터를 1장까지 선택하여 슬리프시킨다. | N31: id_0030.jpg | O31: =COUNTIF(Abilities!$A:$A,A31) -> 1 | P31: 716x1000 168KB
A32: id_0031 | B32: char | C32: green | D32: 3 | F32: 3000 | G32: 1 | J32: 服部静華 | K32: P01 | L32: 【ターン①】自分の現場にいる【緑】のキャラがアクション[キャラ]したとき、カードを1枚引き、手札を1枚リムーブする。 【ヒラメキ】(証拠からリムーブされるときに発動する)カードを1枚引く。 | M32: 【턴①】자신의 현장에 있는 【녹】 캐릭터가 액션[캐릭터]했을 때, 카드를 1장 뽑고 손패를 1장 리무브한다. 【힌트(ヒラメキ)】(증거에서 리무브될 때 발동한다) 카드를 1장 뽑는다. | N32: id_0031.jpg | O32: =COUNTIF(Abilities!$A:$A,A32) -> 2 | P32: 716x1000 232KB
A33: id_0032 | B33: char | C33: green | D33: 6 | F33: 6000 | G33: 1 | I33: 警察,大阪府警 | J33: 服部平蔵 | K33: P01 | L33: 【自分ターン中】自分の現場にいるこのキャラ以外の【緑】のキャラをAP＋1000する。 【ヒラメキ】(証拠からリムーブされるときに発動する)カードを1枚引く。 | M33: 【자신 턴 중】 자신의 현장에 있는 이 캐릭터 이외의 【녹】 캐릭터를 AP+1000 한다. 【히라메키】(증거에서 리무브될 때 발동한다) 카드를 1장 뽑는다. | N33: id_0032.jpg | O33: =COUNTIF(Abilities!$A:$A,A33) -> 2 | P33: 716x1000 225KB
A34: id_0033 | B34: event | C34: green | D34: 5 | J34: 「かっ…和葉ァ!!!」 | K34: P01 | L34: このイベントを自分の現場にいる【緑】のキャラ1枚にセットする。 このイベントがセットされているキャラが相手の能力や効果、コンタクトによって現場から離れるとき、このイベントをリムーブし、そのキャラは現場から離れる代わりに現場に残る。 | M34: 이 이벤트를 자신의 현장에 있는 【녹색】 캐릭터 1장에게 세트한다. 이 이벤트가 세트되어 있는 캐릭터가 상대의 능력이나 효과, 컨택트에 의해 현장에서 떠날 때, 이 이벤트를 리무브하고, 그 캐릭터는 현장에서 떠나는 대신 현장에 남는다. | N34: id_0033.jpg | O34: =COUNTIF(Abilities!$A:$A,A34) -> 2 | P34: 716x1000 266KB
A35: id_0034 | B35: event | C35: green | D35: 3 | J35: 「オレの和葉に何さらしとんじゃ!!!」 | K35: D06 | L35: キャラを1枚まで選び、スリープさせる。カードを1枚引く。 【ヒラメキ】(証拠からリムーブされるときに発動する)キャラを1枚まで選び、スリープさせる。 | M35: 캐릭터를 1장까지 선택하여 슬립시킨다. 카드를 1장 뽑는다. 【히라메키】(증거에서 리무브될 때 발동한다) 캐릭터를 1장까지 선택하여 슬립시킨다. | N35: id_0034.jpg | O35: =COUNTIF(Abilities!$A:$A,A35) -> 2 | P35: 716x1000 231KB
A36: id_0035 | B36: case | C36: green | D36: 7 | E36: 6 | J36: コナンと平次 恋の暗号 | K36: P01 | N36: id_0035.jpg | O36: =COUNTIF(Abilities!$A:$A,A36) -> 0 | P36: 1000x716 185KB
A37: id_0036 | B37: char | C37: white | D37: 8 | F37: 7000 | G37: 2 | I37: 怪盗 | J37: 怪盗キッド | K37: P01 | L37: 【パートナー(白)】【登場時】自分のデッキのカードを上から7枚リムーブしてもよい。 そうした場合、キャラを1枚まで選び、デッキの下に移す。 | M37: 【파트너(백)】【등장 시】 자신의 덱의 카드를 위에서 7장 리무브해도 좋다. 그렇게 한 경우, 캐릭터를 1장까지 골라 덱의 아래로 옮긴다. | N37: id_0036.jpg | O37: =COUNTIF(Abilities!$A:$A,A37) -> 1 | P37: 716x1000 177KB
A38: id_0037 | B38: char | C38: blue | D38: 6 | F38: 5000 | G38: 1 | H38: misread1 | I38: 高校生 | J38: 中森青子 | K38: P01 | L38: ミスリード1（相手の推理に対し、スリープさせることでLP－1する） 【ターン①】相手の現場にいるキャラが推理かアクションしたとき、自分のデッキのカードを上から5枚リムーブしてもよい。そうした場合、ターン終了時までそのキャラを元のLPを0にし、元のAPを0にする。 | M38: 미스리드 1 (상대의 추리에 대해, 슬리프시킴으로써 LP-1 한다) 【턴①】상대의 현장에 있는 캐릭터가 추리나 액션을 했을 때, 자신의 덱 카드를 위에서 5장 리무브해도 된다. 그렇게 한 경우, 턴 종료 시까지 그 캐릭터의 원래 LP를 0으로 하고, 원래 AP를 0으로 한다. | N38: id_0037.jpg | O38: =COUNTIF(Abilities!$A:$A,A38) -> 2 | P38: 716x1000 195KB
A39: id_0038 | B39: char | C39: white | D39: 5 | F39: 6000 | G39: 1 | I39: 怪盗 | J39: 怪盗キッド | K39: P01 | L39: 【ヒラメキ】(証拠からリムーブされるときに発動する) カードを1枚引く。 | M39: 【히라메키】(증거에서 리무브될 때 발동한다) 카드를 1장 뽑는다. | N39: id_0038.jpg | O39: =COUNTIF(Abilities!$A:$A,A39) -> 1 | P39: 716x1000 227KB
A40: id_0039 | B40: char | C40: white | D40: 5 | F40: 4000 | G40: 1 | I40: 高校生 | J40: 黒羽快斗 | K40: P01 | L40: このキャラのアクション終了時、このキャラを現場からデッキの下に移してもよい。そうした場合、手札からレベル6以下の【白】のカード名[黒羽快斗]以外のキャラを1枚まで登場させる。ターン終了時までそのキャラに【突撃】(登場したターンからすぐにアクションできる)と「ターン終了時、このキャラを現場から手札に移す。」を与える。 | M40: 이 캐릭터의 액션 종료 시, 이 캐릭터를 현장에서 덱 아래로 옮겨도 된다. 그렇게 한 경우, 손패에서 레벨 6 이하의 【백】 카드명 [쿠로바 카이토] 이외의 캐릭터를 1장까지 등장시킨다. 턴 종료 시까지 그 캐릭터에게 【돌격】(등장한 턴부터 바로 액션할 수 있다)과 「턴 종료 시, 이 캐릭터를 현장에서 손패로 옮긴다.」를 부여한다. | N40: id_0039.jpg | O40: =COUNTIF(Abilities!$A:$A,A40) -> 1 | P40: 716x1000 179KB
A41: id_0040 | B41: char | C41: white | D41: 5 | F41: 5000 | G41: 1 | I41: 高校生,鈴木財閥 | J41: 鈴木園子 | K41: P01 | L41: 【宣言】【スリープ】：自分のデッキのカードを上から3枚見る。その中からカードを1枚手札に加え、残りを好きな順番でデッキの下に移す。 【ヒラメキ】(証拠からリムーブされるときに発動する)キャラを1枚まで選び、スリープさせる。 | M41: 【선언】【슬립】: 자신의 덱 카드를 위에서 3장 본다. 그 중에서 카드를 1장 손패에 넣고, 나머지는 원하는 순서로 덱 아래에 둔다. 【번뜩임】(증거에서 리무브될 때 발동한다) 캐릭터를 1장까지 선택하고, 슬립시킨다. | N41: id_0040.jpg | O41: =COUNTIF(Abilities!$A:$A,A41) -> 2 | P41: 716x1000 222KB
A42: id_0041 | B42: char | C42: white | D42: 3 | F42: 3000 | G42: 1 | I42: 怪盗 | J42: 怪盗キッド | K42: P01 | L42: 【自分ターン中】相手の現場にキャラが3枚以上いる場合、このキャラをAP+2000する。 | M42: 【자신 턴 중】 상대의 현장에 캐릭터가 3장 이상 있는 경우, 이 캐릭터는 AP+2000 된다. | N42: id_0041.jpg | O42: =COUNTIF(Abilities!$A:$A,A42) -> 1 | P42: 716x1000 192KB
A43: id_0042 | B43: char | C43: white | D43: 6 | F43: 4000 | G43: 2 | I43: 怪盗 | J43: 怪盗1412号 | K43: P01 | L43: このキャラはスリープ状態で登場する。 【登場時】自分のデッキのカードを上から1枚公開する。公開したカードが【白】のカードの場合、手札に加える。公開したカードがそれ以外の場合、デッキの下に移す。 【ヒラメキ】(証拠からリムーブされるときに発動する)カードを1枚引く。 | M43: 이 캐릭터는 슬리프 상태로 등장한다. 【등장 시】 자신의 덱 카드를 위에서 1장 공개한다. 공개한 카드가 【백】 카드인 경우 손패에 추가한다. 공개한 카드가 그 이외인 경우 덱 아래로 옮긴다. 【히라메키】(증거에서 리무브될 때 발동한다) 카드를 1장 뽑는다. | N43: id_0042.jpg | O43: =COUNTIF(Abilities!$A:$A,A43) -> 3 | P43: 716x1000 213KB
A44: id_0043 | B44: char | C44: white | D44: 7 | F44: 6000 | G44: 0 | H44: assault-char | I44: 高校生,空手家 | J44: 京極真 | K44: P01 | L44: 突撃【キャラ】(登場したターンからすぐにキャラを指定してアクションできる) このキャラは事件を指定してアクションできない。 【自分ターン中】AP+1000 | M44: 돌격【캐릭터】(등장한 턴부터 바로 캐릭터를 지정해서 액션할 수 있다) 이 캐릭터는 사건을 지정해서 액션할 수 없다. 【자신 턴 중】AP+1000 | N44: id_0043.jpg | O44: =COUNTIF(Abilities!$A:$A,A44) -> 3 | P44: 716x1000 216KB
...

Sheet Abilities
A1: card_id | B1: ab_index | C1: ic | D1: txt | E1: lim | F1: cond | G1: tgt | H1: cost | I1: ops | J1: v | K1: kw | L1: evs | M1: who | N1: sf | O1: ap | P1: sub | Q1: pa | R1: ef | S1: by | T1: g | U1: hay | V1: k | W1: pk | X1: lp | Y1: per | Z1: lv | AA1: cz | AB1: tr | AC1: tself | AD1: nm | AE1: st | AF1: tApLow | AG1: tf | AH1: alt | AI1: lvd | AJ1: az | AK1: hself | AL1: hw | AM1: sw | AN1: fromHand | AO1: on | AP1: bang | AQ1: dself | AR1: first | AS1: fromRem | AT1: fromUp | AU1: gab | AV1: incl | AW1: rep | AX1: ops_count
A2: id_0001 | B2: 0 | C2: onhint | D2: 【パートナー(青)】【ターン1】自分がネクストヒントで手札を使用したとき、そのカードのレベル以下のレベルのキャラを1枚まで選び、デッキの下に移す。 | E2: 1 | F2: {"pcolor":"blue"} | I2: →Ops | AX2: 1
A3: id_0002 | B3: 0 | C3: static | D3: 【絆】江戸川コナン 相手の能力や効果によって選ばれない。 | F3: {"bond":"江戸川コナン"} | G3: {"sel":"self"} | K3: untarget | AX3: 0
A4: id_0002 | B4: 1 | C4: declare | D4: 【宣言】【スリープ】:手札からレベル5以下の特徴[少年探偵団]のキャラを1枚まで登場させる。カード名[江戸川コナン]を登場させた場合、カードを1枚引く。 | H4: [{"c":"sleepSelf","n":1}] | I4: →Ops | AX4: 2
A5: id_0003 | B5: 0 | C5: onkill | D5: 相手の現場にいるキャラがこのキャラとのコンタクトによってリムーブされたとき、カードを1枚引く。 | I5: →Ops | AX5: 1
A6: id_0003 | B6: 1 | C6: declare | D6: 【パートナー(青)】【宣言】【ターン1】手札を1枚リムーブする:ターン終了時までこのキャラをAP+1000し、突撃(登場したターンからすぐにアクションできる)を持つ。 | E6: 1 | F6: {"pcolor":"blue"} | H6: [{"c":"discard","n":1}] | I6: →Ops | AX6: 2
A7: id_0004 | B7: 0 | C7: flash | D7: 【ヒラメキ】(証拠からリムーブされるときに発動する) カードを1枚引く。 | I7: →Ops | AX7: 1
A8: id_0005 | B8: 0 | C8: hand | D8: 【パートナー】【青】お互いの現場にキャラが合わせて6枚以上いる場合、手札にあるこのキャラはレベル4になる。 | F8: {"pcolor":"blue","fieldMin":6} | Z8: 4 | AX8: 0
A9: id_0005 | B9: 1 | C9: declare | D9: 【宣言】デッキの下に移す:LP0以下の【青】のキャラを1枚まで選び、アクティブにする。 | H9: [{"c":"selfBottom","n":1}] | I9: →Ops | AX9: 1
A10: id_0006 | B10: 0 | C10: onkill | D10: 相手の現場にいるキャラがこのキャラとのコンタクトによってリムーブされたとき、手札を1枚リムーブしてもよい。そうした場合、自分は証拠を1つ得る。 | I10: →Ops | AX10: 2
A11: id_0007 | B11: 0 | C11: enter | D11: このキャラはスリープ状態で登場する。 | AE11: s | AX11: 0
A12: id_0007 | B12: 1 | C12: flash | D12: 【ヒラメキ】(証拠からリムーブされるときに発動する)カードを1枚引く。 | I12: →Ops | AX12: 1
A13: id_0008 | B13: 0 | C13: onally | D13: 【ターン1】能力や効果によってレベル6以下の特徴[少年探偵団]のキャラが自分の現場に登場したとき、その中から1枚をアクティブにし、ターン終了時までそのキャラに迅速(登場したターンからすぐに推理かアクションできる)を与える。 | E13: 1 | I13: →Ops | R13: {"trait":"少年探偵団","lvMax":6,"own":"self"} | AO13: {"by":"effect"} | AX13: 2
A14: id_0009 | B14: 0 | C14: onplay | D14: 【登場時】自分のデッキのカードを上から2枚見る。その中からLP0の【青】のキャラを1枚まで公開して手札に加え、残りを好きな順番でデッキの下に移す。 | I14: →Ops | AX14: 1
A15: id_0010 | B15: 0 | C15: onplay | D15: 【登場時】レベル3以上のキャラの能力やレベル3以上のイベントの効果によって登場した場合、レベル5以下のキャラを1枚まで選び、スリープさせる。 | F15: {"via":[{"type":"char","lvMin":3},{"type":"event","lvMin":3}]} | I15: →Ops | AX15: 1
A16: id_0011 | B16: 0 | C16: onplay | D16: 【登場時】レベル3以上のキャラの能力やレベル3以上のイベントの効果によって登場した場合、キャラを1枚まで選び、ターン終了時までAP+2000する。 | F16: {"via":[{"type":"char","lvMin":3},{"type":"event","lvMin":3}]} | I16: →Ops | AX16: 1
A17: id_0012 | B17: 0 | C17: onplay | D17: 【登場時】自分のデッキのカードを上から4枚見る。その中から【青】のカードを1枚まで公開して手札に加え、残りを好きな順番でデッキの下に移す。カードを手札に加えた場合、手札を1枚リムーブする。 | I17: →Ops | AX17: 2
A18: id_0012 | B18: 1 | C18: flash | D18: 【ヒラメキ】(証拠からリムーブされるときに発動する)カードを1枚引く。 | I18: →Ops | AX18: 1
A19: id_0013 | B19: 0 | C19: ontrig | D19: このキャラが推理したとき、自分のデッキのカードを上から2枚見る。その中から特徴[探偵]のキャラを1枚まで公開して手札に加え、残りを好きな順番でデッキの下に移す。 | I19: →Ops | L19: ["reason"] | P19: self | AX19: 1
A20: id_0013 | B20: 1 | C20: flash | D20: 【ヒラメキ】(証拠からリムーブされるときに発動する)カードを1枚引く。 | I20: →Ops | AX20: 1
A21: id_0014 | B21: 0 | C21: onremoved | D21: 【相手ターン中】【現場リムーブ時】自分のデッキのカードを上からカード名[江戸川コナン]が出るまで1枚ずつ公開し、それを手札に加える。残りの公開したカードをデッキの下に移し、デッキをシャッフルする。 | F21: {"turn":"opp"} | I21: →Ops | AX21: 1
A22: id_0014 | B22: 1 | C22: flash | D22: 【ヒラメキ】(証拠からリムーブされるときに発動する)カードを1枚引く。 | I22: →Ops | AX22: 1
A23: id_0015 | B23: 0 | C23: cutin | D23: 【カットイン】AP+2000(コンタクト中に手札からリムーブして使う) | J23: 2000 | AX23: 0
A24: id_0016 | B24: 0 | C24: static | D24: このキャラがスリープ状態の場合、相手は自分の現場にいるレベル4以下のキャラを指定してアクションできない。 | F24: {"selfSt":"s"} | G24: {"sel":"allies","filter":{"lvMax":4}} | K24: noact | AX24: 0
A25: id_0016 | B25: 1 | C25: flash | D25: 【ヒラメキ】(証拠からリムーブされるときに発動する)キャラを1枚まで選び、スリープさせる。 | I25: →Ops | AX25: 1
A26: id_0017 | B26: 0 | C26: onplay | D26: 【登場時】レベル3以上のキャラの能力やレベル3以上のイベントの効果によって登場した場合、カードを1枚引く。 | F26: {"via":[{"type":"char","lvMin":3},{"type":"event","lvMin":3}]} | I26: →Ops | AX26: 1
A27: id_0018 | B27: 0 | C27: event | D27: 【パートナー】【青】手札を1枚リムーブする。自分のデッキのカードを上から6枚見る。その中からレベル4以下の特徴[少年探偵団]のキャラを2枚まで登場させ、残りをシャッフルしてデッキの下に移す。 | F27: {"pcolor":"blue"} | I27: →Ops | AX27: 5
A28: id_0019 | B28: 0 | C28: event | D28: 自分のデッキのカードを上から5枚見る。その中からカードを1枚まで手札に加え、残りを好きな順番でデッキの下に移す。このイベントを自分の現場にいるキャラ1枚にセットする。 | I28: →Ops | AX28: 2
A29: id_0019 | B29: 1 | C29: grant | D29: このイベントがセットされているキャラは「このキャラがコンタクトしたとき、そのコンタクト中、このキャラをAP+2000する。」を持つ。 | T29: {"ic":"oncontact","on":{"k":"atk"},"ops":[{"op":"self","do":"ap","v":"2000","until":"contact"}]} | AX29: 0
A30: id_0019 | B30: 2 | C30: flash | D30: 【ヒラメキ】(証拠からリムーブされるときに発動する) カードを1枚引く。 | I30: →Ops | AX30: 1
A31: id_0021 | B31: 0 | C31: static | D31: 【パートナー(緑)】LP+1 | F31: {"pcolor":"green"} | G31: {"sel":"self"} | X31: 1 | AX31: 0
A32: id_0021 | B32: 1 | C32: declare | D32: 【宣言】【スリープ】:カード名[服部平次]のキャラを1枚まで選び、ターン終了時まで突撃(登場したターンからすぐにアクションできる)を与える。 | H32: [{"c":"sleepSelf","n":1}] | I32: →Ops | AX32: 1
A33: id_0022 | B33: 0 | C33: static | D33: このキャラは相手の現場にいるアクティブ状態のキャラを指定してアクションできる。 | G33: {"sel":"self"} | K33: actactive | AX33: 0
A34: id_0022 | B34: 1 | C34: ontrig | D34: このキャラがコンタクトしたとき、そのコンタクト中、このキャラをAP+1000する。 | I34: →Ops | L34: ["contact"] | P34: self | AX34: 1
A35: id_0022 | B35: 2 | C35: ontrig | D35: 【パートナー(緑)】【自分ターン中】【ターン1】このキャラがコンタクトしたとき、このキャラをアクティブにする。 | E35: 1 | F35: {"pcolor":"green","turn":"self"} | I35: →Ops | L35: ["contact"] | P35: self | AX35: 1
A36: id_0023 | B36: 0 | C36: flash | D36: 【ヒラメキ】(証拠からリムーブされるときに発動する)カードを1枚引く。 | I36: →Ops | AX36: 1
A37: id_0024 | B37: 0 | C37: ontrig | D37: 【ターン1】相手の現場にいるキャラがコンタクトによってリムーブされたとき、自分のリムーブエリアにある【カットイン】を持つ【緑】のカードを1枚まで選び、手札に加える。 | E37: 1 | I37: →Ops | L37: ["removed"] | M37: opp | N37: {"type":"char","own":"opp"} | S37: contact | AX37: 1
A38: id_0025 | B38: 0 | C38: ontrig | D38: 相手の現場にいるキャラがコンタクトによってリムーブされたとき、ターン終了時までこのキャラは突撃(登場したターンからすぐにアクションできる)を持つ。 | I38: →Ops | L38: ["removed"] | M38: opp | N38: {"type":"char","own":"opp"} | S38: contact | AX38: 1
A39: id_0026 | B39: 0 | C39: ontrig | D39: 【ターン1】このキャラがアクション[キャラ]したとき、ターン終了時までこのキャラをAP+1000する。 | E39: 1 | I39: →Ops | L39: ["act"] | P39: self | V39: char | AX39: 1
A40: id_0027 | B40: 0 | C40: cutin | D40: 【カットイン】AP+2000(コンタクト中に手札からリムーブして使う) | J40: 2000 | AX40: 0
...

Sheet Ops
A1: card_id | B1: ab_index | C1: op_index | D1: op | E1: filter_own | F1: params
A2: id_0001 | B2: 0 | C2: 0 | D2: select | E2: any | F2: {"n":1,"do":"deckBottom","filter":{"type":"char","lvMax":"used"}}
A3: id_0002 | B3: 1 | C3: 0 | D3: play | F3: {"from":"hand","n":1,"filter":{"trait":"少年探偵団","lvMax":5}}
A4: id_0002 | B4: 1 | C4: 1 | D4: if | F4: {"c":"played","name":"江戸川コナン","ops":[{"op":"draw","n":1}]}
A5: id_0003 | B5: 0 | C5: 0 | D5: draw | F5: {"n":1}
A6: id_0003 | B6: 1 | C6: 0 | D6: self | F6: {"do":"ap","v":"1000"}
A7: id_0003 | B7: 1 | C7: 1 | D7: self | F7: {"do":"kw","v":"assault"}
A8: id_0004 | B8: 0 | C8: 0 | D8: draw | F8: {"n":1}
A9: id_0005 | B9: 1 | C9: 0 | D9: select | E9: any | F9: {"n":1,"filter":{"lpMax":0,"color":"blue"},"do":"active"}
A10: id_0006 | B10: 0 | C10: 0 | D10: discard | F10: {"n":1,"opt":true}
A11: id_0006 | B11: 0 | C11: 1 | D11: if | F11: {"c":"done","ops":[{"op":"gain","n":1}]}
A12: id_0007 | B12: 1 | C12: 0 | D12: draw | F12: {"n":1}
A13: id_0008 | B13: 0 | C13: 0 | D13: ent | F13: {"do":"active"}
A14: id_0008 | B14: 0 | C14: 1 | D14: ent | F14: {"do":"kw","v":"rapid"}
A15: id_0009 | B15: 0 | C15: 0 | D15: look | F15: {"n":2,"filter":{"type":"char","lpMax":0,"color":"blue"},"max":1,"then":"hand","rest":"bottom"}
A16: id_0010 | B16: 0 | C16: 0 | D16: select | E16: any | F16: {"n":1,"filter":{"lvMax":5},"do":"sleep"}
A17: id_0011 | B17: 0 | C17: 0 | D17: select | E17: any | F17: {"n":1,"filter":{},"do":"ap","v":"2000"}
A18: id_0012 | B18: 0 | C18: 0 | D18: look | F18: {"n":4,"filter":{"color":"blue"},"max":1,"then":"hand","rest":"bottom"}
A19: id_0012 | B19: 0 | C19: 1 | D19: if | F19: {"c":"done","ops":[{"op":"discard","n":1,"opt":false}]}
A20: id_0012 | B20: 1 | C20: 0 | D20: draw | F20: {"n":1}
A21: id_0013 | B21: 0 | C21: 0 | D21: look | F21: {"n":2,"filter":{"type":"char","trait":"探偵"},"max":1,"then":"hand","rest":"bottom"}
A22: id_0013 | B22: 1 | C22: 0 | D22: draw | F22: {"n":1}
A23: id_0014 | B23: 0 | C23: 0 | D23: reveal | F23: {"then":"hand","rest":"shuffleBottom","shuffle":true,"name":"江戸川コナン"}
A24: id_0014 | B24: 1 | C24: 0 | D24: draw | F24: {"n":1}
A25: id_0016 | B25: 1 | C25: 0 | D25: select | E25: any | F25: {"n":1,"filter":{},"do":"sleep"}
A26: id_0017 | B26: 0 | C26: 0 | D26: draw | F26: {"n":1}
A27: id_0018 | B27: 0 | C27: 0 | D27: discard | F27: {"n":1,"opt":false}
A28: id_0018 | B28: 0 | C28: 1 | D28: peek | F28: {"n":6,"reveal":false}
A29: id_0018 | B29: 0 | C29: 2 | D29: pick | F29: {"from":"seen","as":"chosen","reveal":false,"filter":{"type":"char","trait":"少年探偵団","lvMax":4},"n":2}
A30: id_0018 | B30: 0 | C30: 3 | D30: mv | F30: {"ref":"chosen","to":"field"}
A31: id_0018 | B31: 0 | C31: 4 | D31: mv | F31: {"ref":"rest","to":"deckBottom","order":"shuffle"}
A32: id_0019 | B32: 0 | C32: 0 | D32: look | F32: {"n":5,"filter":{},"max":1,"then":"hand","rest":"bottom"}
A33: id_0019 | B33: 0 | C33: 1 | D33: set
A34: id_0019 | B34: 2 | C34: 0 | D34: draw | F34: {"n":1}
A35: id_0021 | B35: 1 | C35: 0 | D35: select | E35: any | F35: {"n":1,"filter":{"name":"服部平次"},"do":"kw","v":"assault"}
A36: id_0022 | B36: 1 | C36: 0 | D36: self | F36: {"do":"ap","v":"1000","until":"contact"}
A37: id_0022 | B37: 2 | C37: 0 | D37: self | F37: {"do":"active"}
A38: id_0023 | B38: 0 | C38: 0 | D38: draw | F38: {"n":1}
A39: id_0024 | B39: 0 | C39: 0 | D39: fetch | F39: {"n":1,"from":"rem","filter":{"hasIc":"cutin","color":"green"}}
A40: id_0025 | B40: 0 | C40: 0 | D40: self | F40: {"do":"kw","v":"assault"}
...

Sheet CardExtra
A1: card_id | B1: key | C1: value

Sheet Meta
A1: key | B1: value
A2: decks | B2: {}

Sheet Lists
A1: type | B1: color | C1: ic | D1: op | E1: own | F1: ※ 현재 cards.json 에 실제 존재하는 값입니다 (참고/드롭다운용).
A2: case | B2: black | C2: cutin | D2: blankAb | E2: self
A3: char | B3: blue | C3: deckfree | D3: blockActGain | E3: opp
A4: event | B4: blue/black | C4: declare | D4: bottomSame | E4: any
A5: partner | B5: blue/green | C5: disguise | D5: charToEvid
B6: blue/white | C6: enter | D6: choose
B7: blue/yellow | C7: event | D7: chooseMulti
B8: green | C8: flash | D8: contact
B9: green/blue | C9: grant | D9: deckRemSome
B10: green/white | C10: hand | D10: deckSink
B11: green/yellow | C11: ignorecolor | D11: deckToFile
B12: purple | C12: mr | D12: deckrem
B13: red | C13: onact | D13: delay
B14: red/black | C14: onally | D14: discard
B15: red/blue | C15: onallycontact | D15: draw
B16: red/blue/green/yellow | C16: onallykill | D16: ent
B17: red/blue/green/yellow/white/black | C17: onallyremoved | D17: entDo
... B23: yellow/black | C23: onkill | D23: flashFlipped
C24: onmain | D24: flashPickOne
C25: onplay | D25: flip
C26: onreason | D26: flipAllEvid
C27: onremleave | D27: flipDown
C28: onremoved | D28: flipEvid
C29: onsolve | D29: flipTopEvid
C30: ontrig | D30: gain
C31: replace | D31: handTo
C32: static | D32: hayIgn
C33: usecond | D33: if
C34: winalt | D34: ifCost
D35: ifLeft
D36: ifSelf
D37: ifUse
D38: ifc
D39: invest2
D40: investigate
D41: look
D42: loseEvid
D43: lvBudgetRm
D44: moveSet
D45: moveUnder
...
